<?xml version="1.0"?>
    <robot name="disk">
        <link name="world">
            <inertial>
                <mass value="0"/>
                <origin rpy="0 0 0" xyz="0 0 0"/>
                <inertia ixx="0" ixy="0" ixz="0" iyy="0" iyz="0" izz="0"/>
            </inertial>
        </link>

        <joint name="y_to_world" type="prismatic">
            <parent link="world"/>
            <child link="y_prismatic"/>
            <axis xyz="0 1 0"/>
            <limit effort="0.0" lower="1" upper="-1" velocity="1000.0"/>
            <origin rpy="0 0 0" xyz="0 0 0"/>
        </joint>

        <link name="y_prismatic">
            <inertial>
                <mass value="0.01"/>
                <inertia ixx="0.2125" ixy="-0.005" ixz="0.0225" iyy="0.205" iyz="0.045" izz="0.0125"/>
                <origin rpy="0 0 0" xyz="0 0 0"/>
            </inertial>
        </link>

        <joint name="x_to_y" type="prismatic">
            <parent link="y_prismatic"/>
            <child link="x_prismatic"/>
            <axis xyz="1 0 0"/>
            <limit effort="0.0" lower="1" upper="-1" velocity="1000.0"/>
            <origin rpy="0 0 0" xyz="0 0 0"/>
        </joint>

        <link name="x_prismatic">
            <inertial>
                <mass value="0.01"/>
                <inertia ixx="0.2125" ixy="-0.005" ixz="0.0225" iyy="0.205" iyz="0.045" izz="0.0125"/>
                <origin rpy="0 0 0" xyz="0 0 0"/>
            </inertial>
        </link>

        <joint name="base_to_x" type="continuous">
            <parent link="x_prismatic"/>
            <child link="base_link"/>
            <axis xyz="0 0 1"/>
            <origin rpy="0 0 0" xyz="0 0 0"/>
        </joint>

        <link name="base_link">
            <visual>
                <origin xyz="0 0 0.005" rpy="0 0 0"/>
                <geometry>
                    <cylinder length="0.01" radius="0.1"/>
                </geometry>
                <material name="agent_color">
                    <color rgba="0 0.5 1 1"/>
                </material>
            </visual>

            <collision>
                <origin xyz="0 0 0.005" rpy="0 0 0"/>
                <geometry>
                    <cylinder length="0.01" radius="0.1"/>
                </geometry>
            </collision>

            <inertial>
                <origin xyz="0 0 0" rpy="0 0 0"/>
                <mass value="1.0"/>
                <inertia ixx="0.002508" ixy="0" ixz="0" iyy="0.002508" iyz="0" izz="0.005000"/>
            </inertial>
        </link>

        <joint name= "block_to_base" type="fixed">
            <parent link="base_link"/>
            <child link="heading_block"/>
            <origin xyz="0.05 0 0.005" rpy="0 0 0"/>
        </joint>

        <link name="heading_block">
            <visual>
                <origin xyz="0.05 0 0.005" rpy="0 0 0"/>
                <geometry>
                    <box size="0.1 0.01 0.01"/>
                </geometry>
                <material name="block_color"><color rgba="0 0 1 1"/></material>
            </visual>
        </link>
    </robot>
    